<?xml version="1.0" ?>
<sdf version="1.9">
  <model name="simple_lidar_bot">
    <static>false</static>

    <link name="base_link">
      <pose>0 0 0.1 0 0 0</pose>

      <inertial>
        <mass>5.0</mass>
        <inertia>
          <ixx>0.1</ixx>
          <iyy>0.1</iyy>
          <izz>0.1</izz>
          <ixy>0.0</ixy>
          <ixz>0.0</ixz>
          <iyz>0.0</iyz>
        </inertia>
      </inertial>

      <collision name="base_collision">
        <geometry>
          <box>
            <size>0.5 0.3 0.2</size>
          </box>
        </geometry>
      </collision>

      <visual name="base_visual">
        <geometry>
          <box>
            <size>0.5 0.3 0.2</size>
          </box>
        </geometry>
        <material>
          <ambient>0 0 0 1</ambient>
          <diffuse>0 0 0 1</diffuse>
        </material>
      </visual>
    </link>

    <link name="left_wheel">
      <pose>0 0.18 0.05 1.5708 0 0</pose>
      <inertial>
        <mass>0.5</mass>
        <inertia>
          <ixx>0.01</ixx>
          <iyy>0.01</iyy>
          <izz>0.01</izz>
          <ixy>0.0</ixy>
          <ixz>0.0</ixz>
          <iyz>0.0</iyz>
        </inertia>
      </inertial>
      <collision name="left_wheel_collision">
        <geometry>
          <cylinder>
            <radius>0.05</radius>
            <length>0.03</length>
          </cylinder>
        </geometry>
      </collision>
      <visual name="left_wheel_visual">
        <geometry>
          <cylinder>
            <radius>0.05</radius>
            <length>0.03</length>
          </cylinder>
        </geometry>
      </visual>
    </link>

    <link name="right_wheel">
      <pose>0 -0.18 0.05 1.5708 0 0</pose>
      <inertial>
        <mass>0.5</mass>
        <inertia>
          <ixx>0.01</ixx>
          <iyy>0.01</iyy>
          <izz>0.01</izz>
          <ixy>0.0</ixy>
          <ixz>0.0</ixz>
          <iyz>0.0</iyz>
        </inertia>
      </inertial>
      <collision name="right_wheel_collision">
        <geometry>
          <cylinder>
            <radius>0.05</radius>
            <length>0.03</length>
          </cylinder>
        </geometry>
      </collision>
      <visual name="right_wheel_visual">
        <geometry>
          <cylinder>
            <radius>0.05</radius>
            <length>0.03</length>
          </cylinder>
        </geometry>
      </visual>
    </link>

    <joint name="left_wheel_joint" type="revolute">
      <parent>base_link</parent>
      <child>left_wheel</child>
      <axis>
        <xyz>0 0 1</xyz>
      </axis>
    </joint>

    <joint name="right_wheel_joint" type="revolute">
      <parent>base_link</parent>
      <child>right_wheel</child>
      <axis>
        <xyz>0 0 1</xyz>
      </axis>
    </joint>

    <link name="lidar_link">
      <pose>0.2 0 0.2 0 0 0</pose>
      <inertial>
        <mass>0.1</mass>
        <inertia>
          <ixx>0.001</ixx>
          <iyy>0.001</iyy>
          <izz>0.001</izz>
          <ixy>0.0</ixy>
          <ixz>0.0</ixz>
          <iyz>0.0</iyz>
        </inertia>
      </inertial>

      <visual name="lidar_visual">
        <geometry>
          <cylinder>
            <radius>0.03</radius>
            <length>0.05</length>
          </cylinder>
        </geometry>
        <material>
          <ambient>0 0 1 1</ambient>
          <diffuse>0 0 1 1</diffuse>
        </material>
      </visual>

      <sensor name="gpu_lidar" type="gpu_lidar">
        <pose>0 0 0 1.5708 0 0</pose>
        <topic>/simple_lidar_bot/lidar</topic>
        <update_rate>10</update_rate>

        <lidar>
          <scan>
            <horizontal>
              <samples>640</samples>
              <resolution>1</resolution>
              <min_angle>-0.6981317</min_angle>
              <max_angle>0.6981317</max_angle>
            </horizontal>
            <vertical>
              <samples>1</samples>
              <resolution>1</resolution>
              <min_angle>0</min_angle>
              <max_angle>0</max_angle>
            </vertical>
          </scan>

          <range>
            <min>0.08</min>
            <max>10.0</max>
            <resolution>0.01</resolution>
          </range>
        </lidar>

        <always_on>true</always_on>
        <visualize>true</visualize>
      </sensor>
    </link>

    <joint name="lidar_joint" type="fixed">
      <parent>base_link</parent>
      <child>lidar_link</child>
    </joint>

    <plugin
      filename="gz-sim-diff-drive-system"
      name="gz::sim::systems::DiffDrive">
      <left_joint>left_wheel_joint</left_joint>
      <right_joint>right_wheel_joint</right_joint>
      <wheel_separation>0.36</wheel_separation>
      <wheel_radius>0.05</wheel_radius>
      <topic>cmd_vel</topic>
      <odom_topic>odom</odom_topic>
      <tf_topic>tf</tf_topic>
      <frame_id>odom</frame_id>
      <child_frame_id>base_link</child_frame_id>
    </plugin>

  </model>
</sdf>